2020-03-24 09:55:20.922107: W tensorflow/stream_executor/platform/default/dso_loader.cc:55] Could not load dynamic library 'libnvinfer.so.6'; dlerror: libnvinfer.so.6: cannot open shared object file: No such file or directory; LD_LIBRARY_PATH: /.singularity.d/libs
2020-03-24 09:55:20.922842: W tensorflow/stream_executor/platform/default/dso_loader.cc:55] Could not load dynamic library 'libnvinfer_plugin.so.6'; dlerror: libnvinfer_plugin.so.6: cannot open shared object file: No such file or directory; LD_LIBRARY_PATH: /.singularity.d/libs
2020-03-24 09:55:20.922853: W tensorflow/compiler/tf2tensorrt/utils/py_utils.cc:30] Cannot dlopen some TensorRT libraries. If you would like to use Nvidia GPU with TensorRT, please make sure the missing libraries mentioned above are installed properly.
WARNING:tensorflow:From /users/PAS1585/llavez99/.local/lib/python3.5/site-packages/tensorflow_core/python/compat/v2_compat.py:88: disable_resource_variables (from tensorflow.python.ops.variable_scope) is deprecated and will be removed in a future version.
Instructions for updating:
non-resource variables are not supported in the long term
2020-03-24 09:55:32,789	INFO node.py:498 -- Process STDOUT and STDERR is being redirected to /tmp/ray/session_2020-03-24_09-55-32_788770_237621/logs.
2020-03-24 09:55:32,953	INFO services.py:409 -- Waiting for redis server at 127.0.0.1:38561 to respond...
2020-03-24 09:55:33,103	INFO services.py:409 -- Waiting for redis server at 127.0.0.1:18731 to respond...
2020-03-24 09:55:33,103	INFO services.py:809 -- Starting Redis shard with 10.0 GB max memory.
2020-03-24 09:55:33,174	INFO node.py:512 -- Process STDOUT and STDERR is being redirected to /tmp/ray/session_2020-03-24_09-55-32_788770_237621/logs.
2020-03-24 09:55:33,174	WARNING services.py:1301 -- Warning: Capping object memory store to 20.0GB. To increase this further, specify `object_store_memory` when calling ray.init() or ray start.
2020-03-24 09:55:33,174	INFO services.py:1475 -- Starting the Plasma object store with 20.0 GB memory using /dev/shm.
2020-03-24 09:55:33,807	INFO trial_runner.py:176 -- Starting a new experiment.
== Status ==
Using FIFO scheduling algorithm.
Resources requested: 0/3 CPUs, 0/0 GPUs
Memory usage on this node: 10.7/201.2 GB

2020-03-24 09:55:33,814	WARNING signature.py:108 -- The function with_updates has a **kwargs argument, which is currently not supported.
2020-03-24 09:55:33,827	WARNING logger.py:227 -- Could not instantiate <class 'ray.tune.logger.TFLogger'> - skipping.
2020-03-24 09:55:33,829	ERROR log_sync.py:34 -- Log sync requires cluster to be setup with `ray up`.
== Status ==
Using FIFO scheduling algorithm.
Resources requested: 3/3 CPUs, 0/0 GPUs
Memory usage on this node: 10.7/201.2 GB
Result logdir: /users/PAS1585/llavez99/ray_results/construction_traffic
Number of trials: 1 ({'RUNNING': 1})
RUNNING trials:
 - PPO_myEnv-v0_0:	RUNNING

[2m[36m(pid=238026)[0m 2020-03-24 09:55:35.844736: W tensorflow/stream_executor/platform/default/dso_loader.cc:55] Could not load dynamic library 'libnvinfer.so.6'; dlerror: libnvinfer.so.6: cannot open shared object file: No such file or directory; LD_LIBRARY_PATH: /.singularity.d/libs
[2m[36m(pid=238026)[0m 2020-03-24 09:55:35.844820: W tensorflow/stream_executor/platform/default/dso_loader.cc:55] Could not load dynamic library 'libnvinfer_plugin.so.6'; dlerror: libnvinfer_plugin.so.6: cannot open shared object file: No such file or directory; LD_LIBRARY_PATH: /.singularity.d/libs
[2m[36m(pid=238026)[0m 2020-03-24 09:55:35.844831: W tensorflow/compiler/tf2tensorrt/utils/py_utils.cc:30] Cannot dlopen some TensorRT libraries. If you would like to use Nvidia GPU with TensorRT, please make sure the missing libraries mentioned above are installed properly.
[2m[36m(pid=238026)[0m WARNING:tensorflow:From /users/PAS1585/llavez99/.local/lib/python3.5/site-packages/tensorflow_core/python/compat/v2_compat.py:88: disable_resource_variables (from tensorflow.python.ops.variable_scope) is deprecated and will be removed in a future version.
[2m[36m(pid=238026)[0m Instructions for updating:
[2m[36m(pid=238026)[0m non-resource variables are not supported in the long term
[2m[36m(pid=238026)[0m 2020-03-24 09:55:38,846	WARNING ppo.py:143 -- FYI: By default, the value function will not share layers with the policy model ('vf_share_layers': False).
2020-03-24 09:55:38,953	ERROR trial_runner.py:550 -- Error processing event.
Traceback (most recent call last):
  File "/usr/local/lib/python3.5/dist-packages/ray/tune/trial_runner.py", line 498, in _process_trial
    result = self.trial_executor.fetch_result(trial)
  File "/usr/local/lib/python3.5/dist-packages/ray/tune/ray_trial_executor.py", line 342, in fetch_result
    result = ray.get(trial_future[0])
  File "/usr/local/lib/python3.5/dist-packages/ray/worker.py", line 2247, in get
    raise value
ray.exceptions.RayTaskError: [36mray_PPO:train()[39m (pid=238026, host=p0062.ten.osc.edu)
  File "/usr/local/lib/python3.5/dist-packages/ray/rllib/agents/trainer_template.py", line 87, in __init__
    Trainer.__init__(self, config, env, logger_creator)
  File "/usr/local/lib/python3.5/dist-packages/ray/rllib/agents/trainer.py", line 328, in __init__
    Trainable.__init__(self, config, logger_creator)
  File "/usr/local/lib/python3.5/dist-packages/ray/tune/trainable.py", line 99, in __init__
    self._setup(copy.deepcopy(self.config))
  File "/usr/local/lib/python3.5/dist-packages/ray/rllib/agents/trainer.py", line 443, in _setup
    self._init(self.config, self.env_creator)
  File "/usr/local/lib/python3.5/dist-packages/ray/rllib/agents/trainer_template.py", line 106, in _init
    self.config["num_workers"])
  File "/usr/local/lib/python3.5/dist-packages/ray/rllib/agents/trainer.py", line 488, in _make_workers
    logdir=self.logdir)
  File "/usr/local/lib/python3.5/dist-packages/ray/rllib/evaluation/worker_set.py", line 64, in __init__
    RolloutWorker, env_creator, policy, 0, self._local_config)
  File "/usr/local/lib/python3.5/dist-packages/ray/rllib/evaluation/worker_set.py", line 216, in _make_worker
    _fake_sampler=config.get("_fake_sampler", False))
  File "/usr/local/lib/python3.5/dist-packages/ray/rllib/evaluation/rollout_worker.py", line 258, in __init__
    self.env = _validate_env(env_creator(env_context))
  File "/users/PAS1585/llavez99/work/rl_flow/flow/flow/utils/registry.py", line 130, in create_env
    return gym.envs.make(env_name)
  File "/usr/local/lib/python3.5/dist-packages/gym/envs/registration.py", line 156, in make
    return registry.make(id, **kwargs)
  File "/usr/local/lib/python3.5/dist-packages/gym/envs/registration.py", line 101, in make
    env = spec.make(**kwargs)
  File "/usr/local/lib/python3.5/dist-packages/gym/envs/registration.py", line 73, in make
    env = cls(**_kwargs)
  File "/users/PAS1585/llavez99/work/rl_flow/flow/flow/envs/base.py", line 160, in __init__
    self.k.network.generate_network(self.network)
  File "/users/PAS1585/llavez99/work/rl_flow/flow/flow/core/kernel/network/traci.py", line 124, in generate_network
    self.network.net_params)
  File "/users/PAS1585/llavez99/work/rl_flow/flow/flow/core/kernel/network/traci.py", line 613, in generate_net_from_template
    edges_dict, conn_dict = self._import_edges_from_net(net_params)
  File "/users/PAS1585/llavez99/work/rl_flow/flow/flow/core/kernel/network/traci.py", line 843, in _import_edges_from_net
    tree = ElementTree.parse(net_path, parser=parser)
  File "/usr/lib/python3.5/xml/etree/ElementTree.py", line 1184, in parse
    tree.parse(source, parser)
  File "/usr/lib/python3.5/xml/etree/ElementTree.py", line 585, in parse
    source = open(source, "rb")
FileNotFoundError: [Errno 2] No such file or directory: '/mnt/c/Users/llave/Documents/GitHub/flow_osuphysics/lucalavezzo/constructionV4.net.xml'

2020-03-24 09:55:38,960	INFO trial_runner.py:587 -- Attempting to recover trial state from last checkpoint.
2020-03-24 09:55:38,963	WARNING signature.py:108 -- The function with_updates has a **kwargs argument, which is currently not supported.
== Status ==
Using FIFO scheduling algorithm.
Resources requested: 3/3 CPUs, 0/0 GPUs
Memory usage on this node: 10.9/201.2 GB
Result logdir: /users/PAS1585/llavez99/ray_results/construction_traffic
Number of trials: 1 ({'RUNNING': 1})
RUNNING trials:
 - PPO_myEnv-v0_0:	RUNNING, 1 failures: /users/PAS1585/llavez99/ray_results/construction_traffic/PPO_myEnv-v0_0_2020-03-24_09-55-33oikcvixo/error_2020-03-24_09-55-38.txt

[2m[36m(pid=238025)[0m 2020-03-24 09:55:40.555841: W tensorflow/stream_executor/platform/default/dso_loader.cc:55] Could not load dynamic library 'libnvinfer.so.6'; dlerror: libnvinfer.so.6: cannot open shared object file: No such file or directory; LD_LIBRARY_PATH: /.singularity.d/libs
[2m[36m(pid=238025)[0m 2020-03-24 09:55:40.555922: W tensorflow/stream_executor/platform/default/dso_loader.cc:55] Could not load dynamic library 'libnvinfer_plugin.so.6'; dlerror: libnvinfer_plugin.so.6: cannot open shared object file: No such file or directory; LD_LIBRARY_PATH: /.singularity.d/libs
[2m[36m(pid=238025)[0m 2020-03-24 09:55:40.555932: W tensorflow/compiler/tf2tensorrt/utils/py_utils.cc:30] Cannot dlopen some TensorRT libraries. If you would like to use Nvidia GPU with TensorRT, please make sure the missing libraries mentioned above are installed properly.
[2m[36m(pid=238025)[0m WARNING:tensorflow:From /users/PAS1585/llavez99/.local/lib/python3.5/site-packages/tensorflow_core/python/compat/v2_compat.py:88: disable_resource_variables (from tensorflow.python.ops.variable_scope) is deprecated and will be removed in a future version.
[2m[36m(pid=238025)[0m Instructions for updating:
[2m[36m(pid=238025)[0m non-resource variables are not supported in the long term
2020-03-24 09:55:42,972	ERROR trial_runner.py:550 -- Error processing event.
Traceback (most recent call last):
  File "/usr/local/lib/python3.5/dist-packages/ray/tune/trial_runner.py", line 498, in _process_trial
    result = self.trial_executor.fetch_result(trial)
  File "/usr/local/lib/python3.5/dist-packages/ray/tune/ray_trial_executor.py", line 342, in fetch_result
    result = ray.get(trial_future[0])
  File "/usr/local/lib/python3.5/dist-packages/ray/worker.py", line 2247, in get
    raise value
ray.exceptions.RayTaskError: [36mray_PPO:train()[39m (pid=238025, host=p0062.ten.osc.edu)
  File "/usr/local/lib/python3.5/dist-packages/ray/rllib/agents/trainer_template.py", line 87, in __init__
    Trainer.__init__(self, config, env, logger_creator)
  File "/usr/local/lib/python3.5/dist-packages/ray/rllib/agents/trainer.py", line 328, in __init__
    Trainable.__init__(self, config, logger_creator)
  File "/usr/local/lib/python3.5/dist-packages/ray/tune/trainable.py", line 99, in __init__
    self._setup(copy.deepcopy(self.config))
  File "/usr/local/lib/python3.5/dist-packages/ray/rllib/agents/trainer.py", line 443, in _setup
    self._init(self.config, self.env_creator)
  File "/usr/local/lib/python3.5/dist-packages/ray/rllib/agents/trainer_template.py", line 106, in _init
    self.config["num_workers"])
  File "/usr/local/lib/python3.5/dist-packages/ray/rllib/agents/trainer.py", line 488, in _make_workers
    logdir=self.logdir)
  File "/usr/local/lib/python3.5/dist-packages/ray/rllib/evaluation/worker_set.py", line 64, in __init__
    RolloutWorker, env_creator, policy, 0, self._local_config)
  File "/usr/local/lib/python3.5/dist-packages/ray/rllib/evaluation/worker_set.py", line 216, in _make_worker
    _fake_sampler=config.get("_fake_sampler", False))
  File "/usr/local/lib/python3.5/dist-packages/ray/rllib/evaluation/rollout_worker.py", line 258, in __init__
    self.env = _validate_env(env_creator(env_context))
  File "/users/PAS1585/llavez99/work/rl_flow/flow/flow/utils/registry.py", line 130, in create_env
    return gym.envs.make(env_name)
  File "/usr/local/lib/python3.5/dist-packages/gym/envs/registration.py", line 156, in make
    return registry.make(id, **kwargs)
  File "/usr/local/lib/python3.5/dist-packages/gym/envs/registration.py", line 101, in make
    env = spec.make(**kwargs)
  File "/usr/local/lib/python3.5/dist-packages/gym/envs/registration.py", line 73, in make
    env = cls(**_kwargs)
  File "/users/PAS1585/llavez99/work/rl_flow/flow/flow/envs/base.py", line 160, in __init__
    self.k.network.generate_network(self.network)
  File "/users/PAS1585/llavez99/work/rl_flow/flow/flow/core/kernel/network/traci.py", line 124, in generate_network
    self.network.net_params)
  File "/users/PAS1585/llavez99/work/rl_flow/flow/flow/core/kernel/network/traci.py", line 613, in generate_net_from_template
    edges_dict, conn_dict = self._import_edges_from_net(net_params)
  File "/users/PAS1585/llavez99/work/rl_flow/flow/flow/core/kernel/network/traci.py", line 843, in _import_edges_from_net
    tree = ElementTree.parse(net_path, parser=parser)
  File "/usr/lib/python3.5/xml/etree/ElementTree.py", line 1184, in parse
    tree.parse(source, parser)
  File "/usr/lib/python3.5/xml/etree/ElementTree.py", line 585, in parse
    source = open(source, "rb")
FileNotFoundError: [Errno 2] No such file or directory: '/mnt/c/Users/llave/Documents/GitHub/flow_osuphysics/lucalavezzo/constructionV4.net.xml'

2020-03-24 09:55:42,976	INFO trial_runner.py:587 -- Attempting to recover trial state from last checkpoint.
2020-03-24 09:55:42,979	WARNING signature.py:108 -- The function with_updates has a **kwargs argument, which is currently not supported.
[2m[36m(pid=238025)[0m 2020-03-24 09:55:42,963	WARNING ppo.py:143 -- FYI: By default, the value function will not share layers with the policy model ('vf_share_layers': False).
[2m[36m(pid=238027)[0m 2020-03-24 09:55:44.480225: W tensorflow/stream_executor/platform/default/dso_loader.cc:55] Could not load dynamic library 'libnvinfer.so.6'; dlerror: libnvinfer.so.6: cannot open shared object file: No such file or directory; LD_LIBRARY_PATH: /.singularity.d/libs
[2m[36m(pid=238027)[0m 2020-03-24 09:55:44.480315: W tensorflow/stream_executor/platform/default/dso_loader.cc:55] Could not load dynamic library 'libnvinfer_plugin.so.6'; dlerror: libnvinfer_plugin.so.6: cannot open shared object file: No such file or directory; LD_LIBRARY_PATH: /.singularity.d/libs
[2m[36m(pid=238027)[0m 2020-03-24 09:55:44.480326: W tensorflow/compiler/tf2tensorrt/utils/py_utils.cc:30] Cannot dlopen some TensorRT libraries. If you would like to use Nvidia GPU with TensorRT, please make sure the missing libraries mentioned above are installed properly.
[2m[36m(pid=238027)[0m WARNING:tensorflow:From /users/PAS1585/llavez99/.local/lib/python3.5/site-packages/tensorflow_core/python/compat/v2_compat.py:88: disable_resource_variables (from tensorflow.python.ops.variable_scope) is deprecated and will be removed in a future version.
[2m[36m(pid=238027)[0m Instructions for updating:
[2m[36m(pid=238027)[0m non-resource variables are not supported in the long term
2020-03-24 09:55:47,122	ERROR trial_runner.py:550 -- Error processing event.
Traceback (most recent call last):
  File "/usr/local/lib/python3.5/dist-packages/ray/tune/trial_runner.py", line 498, in _process_trial
    result = self.trial_executor.fetch_result(trial)
  File "/usr/local/lib/python3.5/dist-packages/ray/tune/ray_trial_executor.py", line 342, in fetch_result
    result = ray.get(trial_future[0])
  File "/usr/local/lib/python3.5/dist-packages/ray/worker.py", line 2247, in get
    raise value
ray.exceptions.RayTaskError: [36mray_PPO:train()[39m (pid=238027, host=p0062.ten.osc.edu)
  File "/usr/local/lib/python3.5/dist-packages/ray/rllib/agents/trainer_template.py", line 87, in __init__
    Trainer.__init__(self, config, env, logger_creator)
  File "/usr/local/lib/python3.5/dist-packages/ray/rllib/agents/trainer.py", line 328, in __init__
    Trainable.__init__(self, config, logger_creator)
  File "/usr/local/lib/python3.5/dist-packages/ray/tune/trainable.py", line 99, in __init__
    self._setup(copy.deepcopy(self.config))
  File "/usr/local/lib/python3.5/dist-packages/ray/rllib/agents/trainer.py", line 443, in _setup
    self._init(self.config, self.env_creator)
  File "/usr/local/lib/python3.5/dist-packages/ray/rllib/agents/trainer_template.py", line 106, in _init
    self.config["num_workers"])
  File "/usr/local/lib/python3.5/dist-packages/ray/rllib/agents/trainer.py", line 488, in _make_workers
    logdir=self.logdir)
  File "/usr/local/lib/python3.5/dist-packages/ray/rllib/evaluation/worker_set.py", line 64, in __init__
    RolloutWorker, env_creator, policy, 0, self._local_config)
  File "/usr/local/lib/python3.5/dist-packages/ray/rllib/evaluation/worker_set.py", line 216, in _make_worker
    _fake_sampler=config.get("_fake_sampler", False))
  File "/usr/local/lib/python3.5/dist-packages/ray/rllib/evaluation/rollout_worker.py", line 258, in __init__
    self.env = _validate_env(env_creator(env_context))
  File "/users/PAS1585/llavez99/work/rl_flow/flow/flow/utils/registry.py", line 130, in create_env
    return gym.envs.make(env_name)
  File "/usr/local/lib/python3.5/dist-packages/gym/envs/registration.py", line 156, in make
    return registry.make(id, **kwargs)
  File "/usr/local/lib/python3.5/dist-packages/gym/envs/registration.py", line 101, in make
    env = spec.make(**kwargs)
  File "/usr/local/lib/python3.5/dist-packages/gym/envs/registration.py", line 73, in make
    env = cls(**_kwargs)
  File "/users/PAS1585/llavez99/work/rl_flow/flow/flow/envs/base.py", line 160, in __init__
    self.k.network.generate_network(self.network)
  File "/users/PAS1585/llavez99/work/rl_flow/flow/flow/core/kernel/network/traci.py", line 124, in generate_network
    self.network.net_params)
  File "/users/PAS1585/llavez99/work/rl_flow/flow/flow/core/kernel/network/traci.py", line 613, in generate_net_from_template
    edges_dict, conn_dict = self._import_edges_from_net(net_params)
  File "/users/PAS1585/llavez99/work/rl_flow/flow/flow/core/kernel/network/traci.py", line 843, in _import_edges_from_net
    tree = ElementTree.parse(net_path, parser=parser)
  File "/usr/lib/python3.5/xml/etree/ElementTree.py", line 1184, in parse
    tree.parse(source, parser)
  File "/usr/lib/python3.5/xml/etree/ElementTree.py", line 585, in parse
    source = open(source, "rb")
FileNotFoundError: [Errno 2] No such file or directory: '/mnt/c/Users/llave/Documents/GitHub/flow_osuphysics/lucalavezzo/constructionV4.net.xml'

2020-03-24 09:55:47,125	INFO trial_runner.py:587 -- Attempting to recover trial state from last checkpoint.
2020-03-24 09:55:47,128	WARNING signature.py:108 -- The function with_updates has a **kwargs argument, which is currently not supported.
== Status ==
Using FIFO scheduling algorithm.
Resources requested: 3/3 CPUs, 0/0 GPUs
Memory usage on this node: 10.8/201.2 GB
Result logdir: /users/PAS1585/llavez99/ray_results/construction_traffic
Number of trials: 1 ({'RUNNING': 1})
RUNNING trials:
 - PPO_myEnv-v0_0:	RUNNING, 3 failures: /users/PAS1585/llavez99/ray_results/construction_traffic/PPO_myEnv-v0_0_2020-03-24_09-55-33oikcvixo/error_2020-03-24_09-55-47.txt

[2m[36m(pid=238027)[0m 2020-03-24 09:55:47,112	WARNING ppo.py:143 -- FYI: By default, the value function will not share layers with the policy model ('vf_share_layers': False).
[2m[36m(pid=238565)[0m 2020-03-24 09:55:48.881567: W tensorflow/stream_executor/platform/default/dso_loader.cc:55] Could not load dynamic library 'libnvinfer.so.6'; dlerror: libnvinfer.so.6: cannot open shared object file: No such file or directory; LD_LIBRARY_PATH: /.singularity.d/libs
[2m[36m(pid=238565)[0m 2020-03-24 09:55:48.881642: W tensorflow/stream_executor/platform/default/dso_loader.cc:55] Could not load dynamic library 'libnvinfer_plugin.so.6'; dlerror: libnvinfer_plugin.so.6: cannot open shared object file: No such file or directory; LD_LIBRARY_PATH: /.singularity.d/libs
[2m[36m(pid=238565)[0m 2020-03-24 09:55:48.881652: W tensorflow/compiler/tf2tensorrt/utils/py_utils.cc:30] Cannot dlopen some TensorRT libraries. If you would like to use Nvidia GPU with TensorRT, please make sure the missing libraries mentioned above are installed properly.
[2m[36m(pid=238565)[0m WARNING:tensorflow:From /users/PAS1585/llavez99/.local/lib/python3.5/site-packages/tensorflow_core/python/compat/v2_compat.py:88: disable_resource_variables (from tensorflow.python.ops.variable_scope) is deprecated and will be removed in a future version.
[2m[36m(pid=238565)[0m Instructions for updating:
[2m[36m(pid=238565)[0m non-resource variables are not supported in the long term
2020-03-24 09:55:51,439	ERROR trial_runner.py:550 -- Error processing event.
Traceback (most recent call last):
  File "/usr/local/lib/python3.5/dist-packages/ray/tune/trial_runner.py", line 498, in _process_trial
    result = self.trial_executor.fetch_result(trial)
  File "/usr/local/lib/python3.5/dist-packages/ray/tune/ray_trial_executor.py", line 342, in fetch_result
    result = ray.get(trial_future[0])
  File "/usr/local/lib/python3.5/dist-packages/ray/worker.py", line 2247, in get
    raise value
ray.exceptions.RayTaskError: [36mray_PPO:train()[39m (pid=238565, host=p0062.ten.osc.edu)
  File "/usr/local/lib/python3.5/dist-packages/ray/rllib/agents/trainer_template.py", line 87, in __init__
    Trainer.__init__(self, config, env, logger_creator)
  File "/usr/local/lib/python3.5/dist-packages/ray/rllib/agents/trainer.py", line 328, in __init__
    Trainable.__init__(self, config, logger_creator)
  File "/usr/local/lib/python3.5/dist-packages/ray/tune/trainable.py", line 99, in __init__
    self._setup(copy.deepcopy(self.config))
  File "/usr/local/lib/python3.5/dist-packages/ray/rllib/agents/trainer.py", line 443, in _setup
    self._init(self.config, self.env_creator)
  File "/usr/local/lib/python3.5/dist-packages/ray/rllib/agents/trainer_template.py", line 106, in _init
    self.config["num_workers"])
  File "/usr/local/lib/python3.5/dist-packages/ray/rllib/agents/trainer.py", line 488, in _make_workers
    logdir=self.logdir)
  File "/usr/local/lib/python3.5/dist-packages/ray/rllib/evaluation/worker_set.py", line 64, in __init__
    RolloutWorker, env_creator, policy, 0, self._local_config)
  File "/usr/local/lib/python3.5/dist-packages/ray/rllib/evaluation/worker_set.py", line 216, in _make_worker
    _fake_sampler=config.get("_fake_sampler", False))
  File "/usr/local/lib/python3.5/dist-packages/ray/rllib/evaluation/rollout_worker.py", line 258, in __init__
    self.env = _validate_env(env_creator(env_context))
  File "/users/PAS1585/llavez99/work/rl_flow/flow/flow/utils/registry.py", line 130, in create_env
    return gym.envs.make(env_name)
  File "/usr/local/lib/python3.5/dist-packages/gym/envs/registration.py", line 156, in make
    return registry.make(id, **kwargs)
  File "/usr/local/lib/python3.5/dist-packages/gym/envs/registration.py", line 101, in make
    env = spec.make(**kwargs)
  File "/usr/local/lib/python3.5/dist-packages/gym/envs/registration.py", line 73, in make
    env = cls(**_kwargs)
  File "/users/PAS1585/llavez99/work/rl_flow/flow/flow/envs/base.py", line 160, in __init__
    self.k.network.generate_network(self.network)
  File "/users/PAS1585/llavez99/work/rl_flow/flow/flow/core/kernel/network/traci.py", line 124, in generate_network
    self.network.net_params)
  File "/users/PAS1585/llavez99/work/rl_flow/flow/flow/core/kernel/network/traci.py", line 613, in generate_net_from_template
    edges_dict, conn_dict = self._import_edges_from_net(net_params)
  File "/users/PAS1585/llavez99/work/rl_flow/flow/flow/core/kernel/network/traci.py", line 843, in _import_edges_from_net
    tree = ElementTree.parse(net_path, parser=parser)
  File "/usr/lib/python3.5/xml/etree/ElementTree.py", line 1184, in parse
    tree.parse(source, parser)
  File "/usr/lib/python3.5/xml/etree/ElementTree.py", line 585, in parse
    source = open(source, "rb")
FileNotFoundError: [Errno 2] No such file or directory: '/mnt/c/Users/llave/Documents/GitHub/flow_osuphysics/lucalavezzo/constructionV4.net.xml'

2020-03-24 09:55:51,443	INFO trial_runner.py:587 -- Attempting to recover trial state from last checkpoint.
2020-03-24 09:55:51,446	WARNING signature.py:108 -- The function with_updates has a **kwargs argument, which is currently not supported.
[2m[36m(pid=238565)[0m 2020-03-24 09:55:51,429	WARNING ppo.py:143 -- FYI: By default, the value function will not share layers with the policy model ('vf_share_layers': False).
[2m[36m(pid=238731)[0m 2020-03-24 09:55:53.210572: W tensorflow/stream_executor/platform/default/dso_loader.cc:55] Could not load dynamic library 'libnvinfer.so.6'; dlerror: libnvinfer.so.6: cannot open shared object file: No such file or directory; LD_LIBRARY_PATH: /.singularity.d/libs
[2m[36m(pid=238731)[0m 2020-03-24 09:55:53.210660: W tensorflow/stream_executor/platform/default/dso_loader.cc:55] Could not load dynamic library 'libnvinfer_plugin.so.6'; dlerror: libnvinfer_plugin.so.6: cannot open shared object file: No such file or directory; LD_LIBRARY_PATH: /.singularity.d/libs
[2m[36m(pid=238731)[0m 2020-03-24 09:55:53.210670: W tensorflow/compiler/tf2tensorrt/utils/py_utils.cc:30] Cannot dlopen some TensorRT libraries. If you would like to use Nvidia GPU with TensorRT, please make sure the missing libraries mentioned above are installed properly.
